2025-05-05 03:22:52,685 | INFO | logging in using static token
2025-05-05 03:22:53,782 | INFO | Shard ID None has connected to Gateway (Session ID: d2d7608f18f597907bb026fe95420385).
2025-05-05 03:49:37,173 | ERROR | Excepción no capturada
Traceback (most recent call last):
  File "C:\Program Files\Python311\Lib\asyncio\runners.py", line 118, in run
    return self._loop.run_until_complete(task)
           ^^^^^^^^^^^^^^^^^^^^^^^^^^^^^^^^^^^
  File "C:\Program Files\Python311\Lib\asyncio\base_events.py", line 653, in run_until_complete
    return future.result()
           ^^^^^^^^^^^^^^^
  File "c:\Users\ignac\Desktop\cosas PY\discord\bot.py", line 216, in main
  File "C:\Users\ignac\Desktop\cosas PY\discord\botpy\Lib\site-packages\discord\client.py", line 778, in start
    await self.connect(reconnect=reconnect)
  File "C:\Users\ignac\Desktop\cosas PY\discord\botpy\Lib\site-packages\discord\client.py", line 659, in connect
    await self.ws.poll_event()
  File "C:\Users\ignac\Desktop\cosas PY\discord\botpy\Lib\site-packages\discord\gateway.py", line 619, in poll_event
    msg = await self.socket.receive(timeout=self._max_heartbeat_timeout)
          ^^^^^^^^^^^^^^^^^^^^^^^^^^^^^^^^^^^^^^^^^^^^^^^^^^^^^^^^^^^^^^
  File "C:\Users\ignac\Desktop\cosas PY\discord\botpy\Lib\site-packages\aiohttp\client_ws.py", line 334, in receive
    msg = await self._reader.read()
          ^^^^^^^^^^^^^^^^^^^^^^^^^
  File "aiohttp\\_websocket\\reader_c.py", line 118, in read
  File "aiohttp\\_websocket\\reader_c.py", line 115, in aiohttp._websocket.reader_c.WebSocketDataQueue.read
asyncio.exceptions.CancelledError

During handling of the above exception, another exception occurred:

Traceback (most recent call last):
  File "c:\Users\ignac\Desktop\cosas PY\discord\bot.py", line 236, in <module>
  File "C:\Program Files\Python311\Lib\asyncio\runners.py", line 190, in run
    return runner.run(main)
           ^^^^^^^^^^^^^^^^
  File "C:\Program Files\Python311\Lib\asyncio\runners.py", line 123, in run
    raise KeyboardInterrupt()
KeyboardInterrupt
2025-05-05 03:49:44,121 | INFO | logging in using static token
2025-05-05 03:49:45,204 | INFO | Shard ID None has connected to Gateway (Session ID: 46dc35e65af9fce32cee2be7022690c7).
2025-05-05 03:50:01,317 | ERROR | Excepción no capturada
Traceback (most recent call last):
  File "C:\Program Files\Python311\Lib\asyncio\runners.py", line 118, in run
    return self._loop.run_until_complete(task)
           ^^^^^^^^^^^^^^^^^^^^^^^^^^^^^^^^^^^
  File "C:\Program Files\Python311\Lib\asyncio\base_events.py", line 653, in run_until_complete
    return future.result()
           ^^^^^^^^^^^^^^^
  File "c:\Users\ignac\Desktop\cosas PY\discord\bot.py", line 134, in main
    await bot.start(os.getenv("DISCORD_TOKEN"))
  File "C:\Users\ignac\Desktop\cosas PY\discord\botpy\Lib\site-packages\discord\client.py", line 778, in start
    await self.connect(reconnect=reconnect)
  File "C:\Users\ignac\Desktop\cosas PY\discord\botpy\Lib\site-packages\discord\client.py", line 659, in connect
    await self.ws.poll_event()
  File "C:\Users\ignac\Desktop\cosas PY\discord\botpy\Lib\site-packages\discord\gateway.py", line 619, in poll_event
    msg = await self.socket.receive(timeout=self._max_heartbeat_timeout)
          ^^^^^^^^^^^^^^^^^^^^^^^^^^^^^^^^^^^^^^^^^^^^^^^^^^^^^^^^^^^^^^
  File "C:\Users\ignac\Desktop\cosas PY\discord\botpy\Lib\site-packages\aiohttp\client_ws.py", line 334, in receive
    msg = await self._reader.read()
          ^^^^^^^^^^^^^^^^^^^^^^^^^
  File "aiohttp\\_websocket\\reader_c.py", line 118, in read
  File "aiohttp\\_websocket\\reader_c.py", line 115, in aiohttp._websocket.reader_c.WebSocketDataQueue.read
asyncio.exceptions.CancelledError

During handling of the above exception, another exception occurred:

Traceback (most recent call last):
  File "c:\Users\ignac\Desktop\cosas PY\discord\bot.py", line 232, in <module>
    asyncio.run(main())
  File "C:\Program Files\Python311\Lib\asyncio\runners.py", line 190, in run
    return runner.run(main)
           ^^^^^^^^^^^^^^^^
  File "C:\Program Files\Python311\Lib\asyncio\runners.py", line 123, in run
    raise KeyboardInterrupt()
KeyboardInterrupt
2025-05-05 03:50:48,837 | INFO | logging in using static token
2025-05-05 03:50:49,971 | INFO | Shard ID None has connected to Gateway (Session ID: 8c7a80ed99902ac2a1654bc4c73ab2fe).
2025-05-05 03:51:04,569 | ERROR | Excepción no capturada
Traceback (most recent call last):
  File "C:\Program Files\Python311\Lib\asyncio\runners.py", line 118, in run
    return self._loop.run_until_complete(task)
           ^^^^^^^^^^^^^^^^^^^^^^^^^^^^^^^^^^^
  File "C:\Program Files\Python311\Lib\asyncio\base_events.py", line 653, in run_until_complete
    return future.result()
           ^^^^^^^^^^^^^^^
  File "c:\Users\ignac\Desktop\cosas PY\discord\bot.py", line 134, in main
    await bot.start(os.getenv("DISCORD_TOKEN"))
  File "C:\Users\ignac\Desktop\cosas PY\discord\botpy\Lib\site-packages\discord\client.py", line 778, in start
    await self.connect(reconnect=reconnect)
  File "C:\Users\ignac\Desktop\cosas PY\discord\botpy\Lib\site-packages\discord\client.py", line 659, in connect
    await self.ws.poll_event()
  File "C:\Users\ignac\Desktop\cosas PY\discord\botpy\Lib\site-packages\discord\gateway.py", line 619, in poll_event
    msg = await self.socket.receive(timeout=self._max_heartbeat_timeout)
          ^^^^^^^^^^^^^^^^^^^^^^^^^^^^^^^^^^^^^^^^^^^^^^^^^^^^^^^^^^^^^^
  File "C:\Users\ignac\Desktop\cosas PY\discord\botpy\Lib\site-packages\aiohttp\client_ws.py", line 334, in receive
    msg = await self._reader.read()
          ^^^^^^^^^^^^^^^^^^^^^^^^^
  File "aiohttp\\_websocket\\reader_c.py", line 118, in read
  File "aiohttp\\_websocket\\reader_c.py", line 115, in aiohttp._websocket.reader_c.WebSocketDataQueue.read
asyncio.exceptions.CancelledError

During handling of the above exception, another exception occurred:

Traceback (most recent call last):
  File "c:\Users\ignac\Desktop\cosas PY\discord\bot.py", line 232, in <module>
    asyncio.run(main())
  File "C:\Program Files\Python311\Lib\asyncio\runners.py", line 190, in run
    return runner.run(main)
           ^^^^^^^^^^^^^^^^
  File "C:\Program Files\Python311\Lib\asyncio\runners.py", line 123, in run
    raise KeyboardInterrupt()
KeyboardInterrupt
2025-05-05 03:51:33,814 | INFO | logging in using static token
2025-05-05 03:51:34,960 | INFO | Shard ID None has connected to Gateway (Session ID: 9d64ad76032057bfe1eddae90ca25237).
2025-05-05 03:51:47,514 | ERROR | Excepción no capturada
Traceback (most recent call last):
  File "C:\Program Files\Python311\Lib\asyncio\runners.py", line 118, in run
    return self._loop.run_until_complete(task)
           ^^^^^^^^^^^^^^^^^^^^^^^^^^^^^^^^^^^
  File "C:\Program Files\Python311\Lib\asyncio\base_events.py", line 653, in run_until_complete
    return future.result()
           ^^^^^^^^^^^^^^^
  File "c:\Users\ignac\Desktop\cosas PY\discord\bot.py", line 134, in main
    await bot.start(os.getenv("DISCORD_TOKEN"))
  File "C:\Users\ignac\Desktop\cosas PY\discord\botpy\Lib\site-packages\discord\client.py", line 778, in start
    await self.connect(reconnect=reconnect)
  File "C:\Users\ignac\Desktop\cosas PY\discord\botpy\Lib\site-packages\discord\client.py", line 659, in connect
    await self.ws.poll_event()
  File "C:\Users\ignac\Desktop\cosas PY\discord\botpy\Lib\site-packages\discord\gateway.py", line 619, in poll_event
    msg = await self.socket.receive(timeout=self._max_heartbeat_timeout)
          ^^^^^^^^^^^^^^^^^^^^^^^^^^^^^^^^^^^^^^^^^^^^^^^^^^^^^^^^^^^^^^
  File "C:\Users\ignac\Desktop\cosas PY\discord\botpy\Lib\site-packages\aiohttp\client_ws.py", line 334, in receive
    msg = await self._reader.read()
          ^^^^^^^^^^^^^^^^^^^^^^^^^
  File "aiohttp\\_websocket\\reader_c.py", line 118, in read
  File "aiohttp\\_websocket\\reader_c.py", line 115, in aiohttp._websocket.reader_c.WebSocketDataQueue.read
asyncio.exceptions.CancelledError

During handling of the above exception, another exception occurred:

Traceback (most recent call last):
  File "c:\Users\ignac\Desktop\cosas PY\discord\bot.py", line 232, in <module>
    asyncio.run(main())
  File "C:\Program Files\Python311\Lib\asyncio\runners.py", line 190, in run
    return runner.run(main)
           ^^^^^^^^^^^^^^^^
  File "C:\Program Files\Python311\Lib\asyncio\runners.py", line 123, in run
    raise KeyboardInterrupt()
KeyboardInterrupt
2025-05-05 03:57:08,125 | INFO | logging in using static token
2025-05-05 03:57:09,218 | INFO | Shard ID None has connected to Gateway (Session ID: 362e9f5c1a44e0395d459528c8650dbf).
2025-05-05 03:57:17,005 | ERROR | Excepción no capturada
Traceback (most recent call last):
  File "C:\Program Files\Python311\Lib\asyncio\runners.py", line 118, in run
    return self._loop.run_until_complete(task)
           ^^^^^^^^^^^^^^^^^^^^^^^^^^^^^^^^^^^
  File "C:\Program Files\Python311\Lib\asyncio\base_events.py", line 653, in run_until_complete
    return future.result()
           ^^^^^^^^^^^^^^^
  File "c:\Users\ignac\Desktop\cosas PY\discord\bot.py", line 213, in main
    await bot.start(os.getenv("DISCORD_TOKEN"))
  File "C:\Users\ignac\Desktop\cosas PY\discord\botpy\Lib\site-packages\discord\client.py", line 778, in start
    await self.connect(reconnect=reconnect)
  File "C:\Users\ignac\Desktop\cosas PY\discord\botpy\Lib\site-packages\discord\client.py", line 659, in connect
    await self.ws.poll_event()
  File "C:\Users\ignac\Desktop\cosas PY\discord\botpy\Lib\site-packages\discord\gateway.py", line 619, in poll_event
    msg = await self.socket.receive(timeout=self._max_heartbeat_timeout)
          ^^^^^^^^^^^^^^^^^^^^^^^^^^^^^^^^^^^^^^^^^^^^^^^^^^^^^^^^^^^^^^
  File "C:\Users\ignac\Desktop\cosas PY\discord\botpy\Lib\site-packages\aiohttp\client_ws.py", line 334, in receive
    msg = await self._reader.read()
          ^^^^^^^^^^^^^^^^^^^^^^^^^
  File "aiohttp\\_websocket\\reader_c.py", line 118, in read
  File "aiohttp\\_websocket\\reader_c.py", line 115, in aiohttp._websocket.reader_c.WebSocketDataQueue.read
asyncio.exceptions.CancelledError

During handling of the above exception, another exception occurred:

Traceback (most recent call last):
  File "c:\Users\ignac\Desktop\cosas PY\discord\bot.py", line 233, in <module>
    asyncio.run(main())
  File "C:\Program Files\Python311\Lib\asyncio\runners.py", line 190, in run
    return runner.run(main)
           ^^^^^^^^^^^^^^^^
  File "C:\Program Files\Python311\Lib\asyncio\runners.py", line 123, in run
    raise KeyboardInterrupt()
KeyboardInterrupt
2025-05-05 03:59:58,935 | INFO | logging in using static token
2025-05-05 03:59:59,309 | ERROR | Excepción no capturada
Traceback (most recent call last):
  File "C:\Program Files\Python311\Lib\asyncio\runners.py", line 118, in run
    return self._loop.run_until_complete(task)
           ^^^^^^^^^^^^^^^^^^^^^^^^^^^^^^^^^^^
  File "C:\Program Files\Python311\Lib\asyncio\base_events.py", line 653, in run_until_complete
    return future.result()
           ^^^^^^^^^^^^^^^
  File "c:\Users\ignac\Desktop\cosas PY\discord\bot.py", line 135, in main
    await bot.start(os.getenv("DISCORD_TOKEN"))
  File "C:\Users\ignac\Desktop\cosas PY\discord\botpy\Lib\site-packages\discord\client.py", line 777, in start
    await self.login(token)
  File "C:\Users\ignac\Desktop\cosas PY\discord\botpy\Lib\site-packages\discord\client.py", line 614, in login
    self._application = await self.application_info()
                        ^^^^^^^^^^^^^^^^^^^^^^^^^^^^^
  File "C:\Users\ignac\Desktop\cosas PY\discord\botpy\Lib\site-packages\discord\client.py", line 2496, in application_info
    data = await self.http.application_info()
           ^^^^^^^^^^^^^^^^^^^^^^^^^^^^^^^^^^
  File "C:\Users\ignac\Desktop\cosas PY\discord\botpy\Lib\site-packages\discord\http.py", line 625, in request
    async with self.__session.request(method, url, **kwargs) as response:
  File "C:\Users\ignac\Desktop\cosas PY\discord\botpy\Lib\site-packages\aiohttp\client.py", line 1425, in __aenter__
    self._resp: _RetType = await self._coro
                           ^^^^^^^^^^^^^^^^
  File "C:\Users\ignac\Desktop\cosas PY\discord\botpy\Lib\site-packages\aiohttp\client.py", line 730, in _request
    await resp.start(conn)
  File "C:\Users\ignac\Desktop\cosas PY\discord\botpy\Lib\site-packages\aiohttp\client_reqrep.py", line 1059, in start
    message, payload = await protocol.read()  # type: ignore[union-attr]
                       ^^^^^^^^^^^^^^^^^^^^^
  File "C:\Users\ignac\Desktop\cosas PY\discord\botpy\Lib\site-packages\aiohttp\streams.py", line 672, in read
    await self._waiter
asyncio.exceptions.CancelledError

During handling of the above exception, another exception occurred:

Traceback (most recent call last):
  File "c:\Users\ignac\Desktop\cosas PY\discord\bot.py", line 233, in <module>
    asyncio.run(main())
  File "C:\Program Files\Python311\Lib\asyncio\runners.py", line 190, in run
    return runner.run(main)
           ^^^^^^^^^^^^^^^^
  File "C:\Program Files\Python311\Lib\asyncio\runners.py", line 123, in run
    raise KeyboardInterrupt()
KeyboardInterrupt
2025-05-05 04:01:37,270 | INFO | logging in using static token
2025-05-05 04:01:38,419 | INFO | Shard ID None has connected to Gateway (Session ID: 94f9cd7de385865232cf6733da5b9011).
2025-05-05 21:26:20,129 | INFO | logging in using static token
2025-05-05 21:26:21,330 | INFO | Shard ID None has connected to Gateway (Session ID: f5531f4bd8bc2e1dfb05571ae939f5d6).
2025-05-05 22:15:37,676 | INFO | logging in using static token
2025-05-05 22:15:38,955 | INFO | Shard ID None has connected to Gateway (Session ID: e7b30fb3b06e0602366fd5b9f0d982db).
2025-05-05 22:18:36,594 | ERROR | Ignoring exception in command play
Traceback (most recent call last):
  File "C:\Users\ignac\Desktop\cosas PY\discord\botpy\Lib\site-packages\discord\ext\commands\bot.py", line 1350, in invoke
    await ctx.command.invoke(ctx)
  File "C:\Users\ignac\Desktop\cosas PY\discord\botpy\Lib\site-packages\discord\ext\commands\core.py", line 1021, in invoke
    await self.prepare(ctx)
  File "C:\Users\ignac\Desktop\cosas PY\discord\botpy\Lib\site-packages\discord\ext\commands\core.py", line 938, in prepare
    await self._parse_arguments(ctx)
  File "C:\Users\ignac\Desktop\cosas PY\discord\botpy\Lib\site-packages\discord\ext\commands\core.py", line 853, in _parse_arguments
    kwargs[name] = await self.transform(ctx, param, attachments)
                   ^^^^^^^^^^^^^^^^^^^^^^^^^^^^^^^^^^^^^^^^^^^^^
  File "C:\Users\ignac\Desktop\cosas PY\discord\botpy\Lib\site-packages\discord\ext\commands\core.py", line 697, in transform
    raise MissingRequiredArgument(param)
discord.ext.commands.errors.MissingRequiredArgument: url is a required argument that is missing.
2025-05-05 22:18:52,776 | ERROR | Ignoring exception in command None
discord.ext.commands.errors.CommandNotFound: Command "musica" is not found
2025-05-05 22:19:37,026 | ERROR | Ignoring exception in command play
Traceback (most recent call last):
  File "C:\Users\ignac\Desktop\cosas PY\discord\botpy\Lib\site-packages\discord\ext\commands\bot.py", line 1350, in invoke
    await ctx.command.invoke(ctx)
  File "C:\Users\ignac\Desktop\cosas PY\discord\botpy\Lib\site-packages\discord\ext\commands\core.py", line 1021, in invoke
    await self.prepare(ctx)
  File "C:\Users\ignac\Desktop\cosas PY\discord\botpy\Lib\site-packages\discord\ext\commands\core.py", line 938, in prepare
    await self._parse_arguments(ctx)
  File "C:\Users\ignac\Desktop\cosas PY\discord\botpy\Lib\site-packages\discord\ext\commands\core.py", line 853, in _parse_arguments
    kwargs[name] = await self.transform(ctx, param, attachments)
                   ^^^^^^^^^^^^^^^^^^^^^^^^^^^^^^^^^^^^^^^^^^^^^
  File "C:\Users\ignac\Desktop\cosas PY\discord\botpy\Lib\site-packages\discord\ext\commands\core.py", line 697, in transform
    raise MissingRequiredArgument(param)
discord.ext.commands.errors.MissingRequiredArgument: url is a required argument that is missing.
2025-05-05 22:21:15,772 | INFO | Connecting to voice...
2025-05-05 22:21:15,772 | INFO | Starting voice handshake... (connection attempt 1)
2025-05-05 22:21:16,111 | INFO | Voice handshake complete. Endpoint found buenos-aires7166.discord.media
2025-05-05 22:29:23,092 | INFO | logging in using static token
2025-05-05 22:29:24,204 | INFO | Shard ID None has connected to Gateway (Session ID: b127b9d397b8300c794692373fa6bbe1).
2025-05-05 22:30:30,278 | INFO | Connecting to voice...
2025-05-05 22:30:30,278 | INFO | Starting voice handshake... (connection attempt 1)
2025-05-05 22:30:30,564 | INFO | Voice handshake complete. Endpoint found buenos-aires2072.discord.media
2025-05-05 22:30:57,029 | ERROR | Ignoring exception in command musica
Traceback (most recent call last):
  File "C:\Users\ignac\Desktop\cosas PY\discord\botpy\Lib\site-packages\youtube_dl\extractor\youtube.py", line 1360, in _decrypt_signature
    func = self._extract_signature_function(
           ^^^^^^^^^^^^^^^^^^^^^^^^^^^^^^^^^
  File "C:\Users\ignac\Desktop\cosas PY\discord\botpy\Lib\site-packages\youtube_dl\extractor\youtube.py", line 1274, in _extract_signature_function
    res = self._parse_sig_js(code)
          ^^^^^^^^^^^^^^^^^^^^^^^^
  File "C:\Users\ignac\Desktop\cosas PY\discord\botpy\Lib\site-packages\youtube_dl\extractor\youtube.py", line 1343, in _parse_sig_js
    initial_function = jsi.extract_function(funcname)
                       ^^^^^^^^^^^^^^^^^^^^^^^^^^^^^^
  File "C:\Users\ignac\Desktop\cosas PY\discord\botpy\Lib\site-packages\youtube_dl\jsinterp.py", line 245, in extract_function
    raise ExtractorError('Could not find JS function %r' % funcname)
youtube_dl.utils.ExtractorError: Could not find JS function 'decodeURIComponent'; please report this issue on https://yt-dl.org/bug . Make sure you are using the latest version; see  https://yt-dl.org/update  on how to update. Be sure to call youtube-dl with the --verbose flag and include its complete output.

During handling of the above exception, another exception occurred:

Traceback (most recent call last):
  File "C:\Users\ignac\Desktop\cosas PY\discord\botpy\Lib\site-packages\youtube_dl\YoutubeDL.py", line 815, in wrapper
    return func(self, *args, **kwargs)
           ^^^^^^^^^^^^^^^^^^^^^^^^^^^
  File "C:\Users\ignac\Desktop\cosas PY\discord\botpy\Lib\site-packages\youtube_dl\YoutubeDL.py", line 836, in __extract_info
    ie_result = ie.extract(url)
                ^^^^^^^^^^^^^^^
  File "C:\Users\ignac\Desktop\cosas PY\discord\botpy\Lib\site-packages\youtube_dl\extractor\common.py", line 534, in extract
    ie_result = self._real_extract(url)
                ^^^^^^^^^^^^^^^^^^^^^^^
  File "C:\Users\ignac\Desktop\cosas PY\discord\botpy\Lib\site-packages\youtube_dl\extractor\youtube.py", line 1641, in _real_extract
    signature = self._decrypt_signature(sc['s'][0], video_id, player_url)
                ^^^^^^^^^^^^^^^^^^^^^^^^^^^^^^^^^^^^^^^^^^^^^^^^^^^^^^^^^
  File "C:\Users\ignac\Desktop\cosas PY\discord\botpy\Lib\site-packages\youtube_dl\extractor\youtube.py", line 1370, in _decrypt_signature
    raise ExtractorError(
youtube_dl.utils.ExtractorError: Signature extraction failed: Traceback (most recent call last):
  File "C:\Users\ignac\Desktop\cosas PY\discord\botpy\Lib\site-packages\youtube_dl\extractor\youtube.py", line 1360, in _decrypt_signature
    func = self._extract_signature_function(
           ^^^^^^^^^^^^^^^^^^^^^^^^^^^^^^^^^
  File "C:\Users\ignac\Desktop\cosas PY\discord\botpy\Lib\site-packages\youtube_dl\extractor\youtube.py", line 1274, in _extract_signature_function
    res = self._parse_sig_js(code)
          ^^^^^^^^^^^^^^^^^^^^^^^^
  File "C:\Users\ignac\Desktop\cosas PY\discord\botpy\Lib\site-packages\youtube_dl\extractor\youtube.py", line 1343, in _parse_sig_js
    initial_function = jsi.extract_function(funcname)
                       ^^^^^^^^^^^^^^^^^^^^^^^^^^^^^^
  File "C:\Users\ignac\Desktop\cosas PY\discord\botpy\Lib\site-packages\youtube_dl\jsinterp.py", line 245, in extract_function
    raise ExtractorError('Could not find JS function %r' % funcname)
youtube_dl.utils.ExtractorError: Could not find JS function 'decodeURIComponent'; please report this issue on https://yt-dl.org/bug . Make sure you are using the latest version; see  https://yt-dl.org/update  on how to update. Be sure to call youtube-dl with the --verbose flag and include its complete output.
 (caused by ExtractorError("Could not find JS function 'decodeURIComponent'; please report this issue on https://yt-dl.org/bug . Make sure you are using the latest version; see  https://yt-dl.org/update  on how to update. Be sure to call youtube-dl with the --verbose flag and include its complete output.")); please report this issue on https://yt-dl.org/bug . Make sure you are using the latest version; see  https://yt-dl.org/update  on how to update. Be sure to call youtube-dl with the --verbose flag and include its complete output.

During handling of the above exception, another exception occurred:

Traceback (most recent call last):
  File "C:\Users\ignac\Desktop\cosas PY\discord\botpy\Lib\site-packages\discord\ext\commands\core.py", line 235, in wrapped
    ret = await coro(*args, **kwargs)
          ^^^^^^^^^^^^^^^^^^^^^^^^^^^
  File "c:\Users\ignac\Desktop\cosas PY\discord\comandos\musica.py", line 55, in musica
    await self.play(ctx, url=url)
  File "C:\Users\ignac\Desktop\cosas PY\discord\botpy\Lib\site-packages\discord\ext\commands\core.py", line 588, in __call__
    return await self.callback(self.cog, context, *args, **kwargs)  # type: ignore
           ^^^^^^^^^^^^^^^^^^^^^^^^^^^^^^^^^^^^^^^^^^^^^^^^^^^^^^^
  File "c:\Users\ignac\Desktop\cosas PY\discord\comandos\musica.py", line 116, in play
    player = await YTDLSource.from_url(url, loop=self.bot.loop, stream=True)
             ^^^^^^^^^^^^^^^^^^^^^^^^^^^^^^^^^^^^^^^^^^^^^^^^^^^^^^^^^^^^^^^
  File "c:\Users\ignac\Desktop\cosas PY\discord\comandos\musica.py", line 37, in from_url
    data = await loop.run_in_executor(None, lambda: ytdl.extract_info(url, download=not stream))
           ^^^^^^^^^^^^^^^^^^^^^^^^^^^^^^^^^^^^^^^^^^^^^^^^^^^^^^^^^^^^^^^^^^^^^^^^^^^^^^^^^^^^^
  File "C:\Program Files\Python311\Lib\concurrent\futures\thread.py", line 58, in run
    result = self.fn(*self.args, **self.kwargs)
             ^^^^^^^^^^^^^^^^^^^^^^^^^^^^^^^^^^
  File "c:\Users\ignac\Desktop\cosas PY\discord\comandos\musica.py", line 37, in <lambda>
    data = await loop.run_in_executor(None, lambda: ytdl.extract_info(url, download=not stream))
                                                    ^^^^^^^^^^^^^^^^^^^^^^^^^^^^^^^^^^^^^^^^^^^
  File "C:\Users\ignac\Desktop\cosas PY\discord\botpy\Lib\site-packages\youtube_dl\YoutubeDL.py", line 808, in extract_info
    return self.__extract_info(url, ie, download, extra_info, process)
           ^^^^^^^^^^^^^^^^^^^^^^^^^^^^^^^^^^^^^^^^^^^^^^^^^^^^^^^^^^^
  File "C:\Users\ignac\Desktop\cosas PY\discord\botpy\Lib\site-packages\youtube_dl\YoutubeDL.py", line 824, in wrapper
    self.report_error(compat_str(e), e.format_traceback())
  File "C:\Users\ignac\Desktop\cosas PY\discord\botpy\Lib\site-packages\youtube_dl\YoutubeDL.py", line 628, in report_error
    self.trouble(error_message, tb)
  File "C:\Users\ignac\Desktop\cosas PY\discord\botpy\Lib\site-packages\youtube_dl\YoutubeDL.py", line 598, in trouble
    raise DownloadError(message, exc_info)
youtube_dl.utils.DownloadError: ERROR: Signature extraction failed: Traceback (most recent call last):
  File "C:\Users\ignac\Desktop\cosas PY\discord\botpy\Lib\site-packages\youtube_dl\extractor\youtube.py", line 1360, in _decrypt_signature
    func = self._extract_signature_function(
           ^^^^^^^^^^^^^^^^^^^^^^^^^^^^^^^^^
  File "C:\Users\ignac\Desktop\cosas PY\discord\botpy\Lib\site-packages\youtube_dl\extractor\youtube.py", line 1274, in _extract_signature_function
    res = self._parse_sig_js(code)
          ^^^^^^^^^^^^^^^^^^^^^^^^
  File "C:\Users\ignac\Desktop\cosas PY\discord\botpy\Lib\site-packages\youtube_dl\extractor\youtube.py", line 1343, in _parse_sig_js
    initial_function = jsi.extract_function(funcname)
                       ^^^^^^^^^^^^^^^^^^^^^^^^^^^^^^
  File "C:\Users\ignac\Desktop\cosas PY\discord\botpy\Lib\site-packages\youtube_dl\jsinterp.py", line 245, in extract_function
    raise ExtractorError('Could not find JS function %r' % funcname)
youtube_dl.utils.ExtractorError: Could not find JS function 'decodeURIComponent'; please report this issue on https://yt-dl.org/bug . Make sure you are using the latest version; see  https://yt-dl.org/update  on how to update. Be sure to call youtube-dl with the --verbose flag and include its complete output.
 (caused by ExtractorError("Could not find JS function 'decodeURIComponent'; please report this issue on https://yt-dl.org/bug . Make sure you are using the latest version; see  https://yt-dl.org/update  on how to update. Be sure to call youtube-dl with the --verbose flag and include its complete output.")); please report this issue on https://yt-dl.org/bug . Make sure you are using the latest version; see  https://yt-dl.org/update  on how to update. Be sure to call youtube-dl with the --verbose flag and include its complete output.

The above exception was the direct cause of the following exception:

Traceback (most recent call last):
  File "C:\Users\ignac\Desktop\cosas PY\discord\botpy\Lib\site-packages\discord\ext\commands\bot.py", line 1350, in invoke
    await ctx.command.invoke(ctx)
  File "C:\Users\ignac\Desktop\cosas PY\discord\botpy\Lib\site-packages\discord\ext\commands\core.py", line 1029, in invoke
    await injected(*ctx.args, **ctx.kwargs)  # type: ignore
    ^^^^^^^^^^^^^^^^^^^^^^^^^^^^^^^^^^^^^^^
  File "C:\Users\ignac\Desktop\cosas PY\discord\botpy\Lib\site-packages\discord\ext\commands\core.py", line 244, in wrapped
    raise CommandInvokeError(exc) from exc
discord.ext.commands.errors.CommandInvokeError: Command raised an exception: DownloadError: ERROR: Signature extraction failed: Traceback (most recent call last):
  File "C:\Users\ignac\Desktop\cosas PY\discord\botpy\Lib\site-packages\youtube_dl\extractor\youtube.py", line 1360, in _decrypt_signature
    func = self._extract_signature_function(
           ^^^^^^^^^^^^^^^^^^^^^^^^^^^^^^^^^
  File "C:\Users\ignac\Desktop\cosas PY\discord\botpy\Lib\site-packages\youtube_dl\extractor\youtube.py", line 1274, in _extract_signature_function
    res = self._parse_sig_js(code)
          ^^^^^^^^^^^^^^^^^^^^^^^^
  File "C:\Users\ignac\Desktop\cosas PY\discord\botpy\Lib\site-packages\youtube_dl\extractor\youtube.py", line 1343, in _parse_sig_js
    initial_function = jsi.extract_function(funcname)
                       ^^^^^^^^^^^^^^^^^^^^^^^^^^^^^^
  File "C:\Users\ignac\Desktop\cosas PY\discord\botpy\Lib\site-packages\youtube_dl\jsinterp.py", line 245, in extract_function
    raise ExtractorError('Could not find JS function %r' % funcname)
youtube_dl.utils.ExtractorError: Could not find JS function 'decodeURIComponent'; please report this issue on https://yt-dl.org/bug . Make sure you are using the latest version; see  https://yt-dl.org/update  on how to update. Be sure to call youtube-dl with the --verbose flag and include its complete output.
 (caused by ExtractorError("Could not find JS function 'decodeURIComponent'; please report this issue on https://yt-dl.org/bug . Make sure you are using the latest version; see  https://yt-dl.org/update  on how to update. Be sure to call youtube-dl with the --verbose flag and include its complete output.")); please report this issue on https://yt-dl.org/bug . Make sure you are using the latest version; see  https://yt-dl.org/update  on how to update. Be sure to call youtube-dl with the --verbose flag and include its complete output.
2025-05-05 22:31:16,481 | ERROR | Ignoring exception in command play
Traceback (most recent call last):
  File "C:\Users\ignac\Desktop\cosas PY\discord\botpy\Lib\site-packages\youtube_dl\extractor\youtube.py", line 1360, in _decrypt_signature
    func = self._extract_signature_function(
           ^^^^^^^^^^^^^^^^^^^^^^^^^^^^^^^^^
  File "C:\Users\ignac\Desktop\cosas PY\discord\botpy\Lib\site-packages\youtube_dl\extractor\youtube.py", line 1274, in _extract_signature_function
    res = self._parse_sig_js(code)
          ^^^^^^^^^^^^^^^^^^^^^^^^
  File "C:\Users\ignac\Desktop\cosas PY\discord\botpy\Lib\site-packages\youtube_dl\extractor\youtube.py", line 1343, in _parse_sig_js
    initial_function = jsi.extract_function(funcname)
                       ^^^^^^^^^^^^^^^^^^^^^^^^^^^^^^
  File "C:\Users\ignac\Desktop\cosas PY\discord\botpy\Lib\site-packages\youtube_dl\jsinterp.py", line 245, in extract_function
    raise ExtractorError('Could not find JS function %r' % funcname)
youtube_dl.utils.ExtractorError: Could not find JS function 'decodeURIComponent'; please report this issue on https://yt-dl.org/bug . Make sure you are using the latest version; see  https://yt-dl.org/update  on how to update. Be sure to call youtube-dl with the --verbose flag and include its complete output.

During handling of the above exception, another exception occurred:

Traceback (most recent call last):
  File "C:\Users\ignac\Desktop\cosas PY\discord\botpy\Lib\site-packages\youtube_dl\YoutubeDL.py", line 815, in wrapper
    return func(self, *args, **kwargs)
           ^^^^^^^^^^^^^^^^^^^^^^^^^^^
  File "C:\Users\ignac\Desktop\cosas PY\discord\botpy\Lib\site-packages\youtube_dl\YoutubeDL.py", line 836, in __extract_info
    ie_result = ie.extract(url)
                ^^^^^^^^^^^^^^^
  File "C:\Users\ignac\Desktop\cosas PY\discord\botpy\Lib\site-packages\youtube_dl\extractor\common.py", line 534, in extract
    ie_result = self._real_extract(url)
                ^^^^^^^^^^^^^^^^^^^^^^^
  File "C:\Users\ignac\Desktop\cosas PY\discord\botpy\Lib\site-packages\youtube_dl\extractor\youtube.py", line 1641, in _real_extract
    signature = self._decrypt_signature(sc['s'][0], video_id, player_url)
                ^^^^^^^^^^^^^^^^^^^^^^^^^^^^^^^^^^^^^^^^^^^^^^^^^^^^^^^^^
  File "C:\Users\ignac\Desktop\cosas PY\discord\botpy\Lib\site-packages\youtube_dl\extractor\youtube.py", line 1370, in _decrypt_signature
    raise ExtractorError(
youtube_dl.utils.ExtractorError: Signature extraction failed: Traceback (most recent call last):
  File "C:\Users\ignac\Desktop\cosas PY\discord\botpy\Lib\site-packages\youtube_dl\extractor\youtube.py", line 1360, in _decrypt_signature
    func = self._extract_signature_function(
           ^^^^^^^^^^^^^^^^^^^^^^^^^^^^^^^^^
  File "C:\Users\ignac\Desktop\cosas PY\discord\botpy\Lib\site-packages\youtube_dl\extractor\youtube.py", line 1274, in _extract_signature_function
    res = self._parse_sig_js(code)
          ^^^^^^^^^^^^^^^^^^^^^^^^
  File "C:\Users\ignac\Desktop\cosas PY\discord\botpy\Lib\site-packages\youtube_dl\extractor\youtube.py", line 1343, in _parse_sig_js
    initial_function = jsi.extract_function(funcname)
                       ^^^^^^^^^^^^^^^^^^^^^^^^^^^^^^
  File "C:\Users\ignac\Desktop\cosas PY\discord\botpy\Lib\site-packages\youtube_dl\jsinterp.py", line 245, in extract_function
    raise ExtractorError('Could not find JS function %r' % funcname)
youtube_dl.utils.ExtractorError: Could not find JS function 'decodeURIComponent'; please report this issue on https://yt-dl.org/bug . Make sure you are using the latest version; see  https://yt-dl.org/update  on how to update. Be sure to call youtube-dl with the --verbose flag and include its complete output.
 (caused by ExtractorError("Could not find JS function 'decodeURIComponent'; please report this issue on https://yt-dl.org/bug . Make sure you are using the latest version; see  https://yt-dl.org/update  on how to update. Be sure to call youtube-dl with the --verbose flag and include its complete output.")); please report this issue on https://yt-dl.org/bug . Make sure you are using the latest version; see  https://yt-dl.org/update  on how to update. Be sure to call youtube-dl with the --verbose flag and include its complete output.

During handling of the above exception, another exception occurred:

Traceback (most recent call last):
  File "C:\Users\ignac\Desktop\cosas PY\discord\botpy\Lib\site-packages\discord\ext\commands\core.py", line 235, in wrapped
    ret = await coro(*args, **kwargs)
          ^^^^^^^^^^^^^^^^^^^^^^^^^^^
  File "c:\Users\ignac\Desktop\cosas PY\discord\comandos\musica.py", line 116, in play
    player = await YTDLSource.from_url(url, loop=self.bot.loop, stream=True)
             ^^^^^^^^^^^^^^^^^^^^^^^^^^^^^^^^^^^^^^^^^^^^^^^^^^^^^^^^^^^^^^^
  File "c:\Users\ignac\Desktop\cosas PY\discord\comandos\musica.py", line 37, in from_url
    data = await loop.run_in_executor(None, lambda: ytdl.extract_info(url, download=not stream))
           ^^^^^^^^^^^^^^^^^^^^^^^^^^^^^^^^^^^^^^^^^^^^^^^^^^^^^^^^^^^^^^^^^^^^^^^^^^^^^^^^^^^^^
  File "C:\Program Files\Python311\Lib\concurrent\futures\thread.py", line 58, in run
    result = self.fn(*self.args, **self.kwargs)
             ^^^^^^^^^^^^^^^^^^^^^^^^^^^^^^^^^^
  File "c:\Users\ignac\Desktop\cosas PY\discord\comandos\musica.py", line 37, in <lambda>
    data = await loop.run_in_executor(None, lambda: ytdl.extract_info(url, download=not stream))
                                                    ^^^^^^^^^^^^^^^^^^^^^^^^^^^^^^^^^^^^^^^^^^^
  File "C:\Users\ignac\Desktop\cosas PY\discord\botpy\Lib\site-packages\youtube_dl\YoutubeDL.py", line 808, in extract_info
    return self.__extract_info(url, ie, download, extra_info, process)
           ^^^^^^^^^^^^^^^^^^^^^^^^^^^^^^^^^^^^^^^^^^^^^^^^^^^^^^^^^^^
  File "C:\Users\ignac\Desktop\cosas PY\discord\botpy\Lib\site-packages\youtube_dl\YoutubeDL.py", line 824, in wrapper
    self.report_error(compat_str(e), e.format_traceback())
  File "C:\Users\ignac\Desktop\cosas PY\discord\botpy\Lib\site-packages\youtube_dl\YoutubeDL.py", line 628, in report_error
    self.trouble(error_message, tb)
  File "C:\Users\ignac\Desktop\cosas PY\discord\botpy\Lib\site-packages\youtube_dl\YoutubeDL.py", line 598, in trouble
    raise DownloadError(message, exc_info)
youtube_dl.utils.DownloadError: ERROR: Signature extraction failed: Traceback (most recent call last):
  File "C:\Users\ignac\Desktop\cosas PY\discord\botpy\Lib\site-packages\youtube_dl\extractor\youtube.py", line 1360, in _decrypt_signature
    func = self._extract_signature_function(
           ^^^^^^^^^^^^^^^^^^^^^^^^^^^^^^^^^
  File "C:\Users\ignac\Desktop\cosas PY\discord\botpy\Lib\site-packages\youtube_dl\extractor\youtube.py", line 1274, in _extract_signature_function
    res = self._parse_sig_js(code)
          ^^^^^^^^^^^^^^^^^^^^^^^^
  File "C:\Users\ignac\Desktop\cosas PY\discord\botpy\Lib\site-packages\youtube_dl\extractor\youtube.py", line 1343, in _parse_sig_js
    initial_function = jsi.extract_function(funcname)
                       ^^^^^^^^^^^^^^^^^^^^^^^^^^^^^^
  File "C:\Users\ignac\Desktop\cosas PY\discord\botpy\Lib\site-packages\youtube_dl\jsinterp.py", line 245, in extract_function
    raise ExtractorError('Could not find JS function %r' % funcname)
youtube_dl.utils.ExtractorError: Could not find JS function 'decodeURIComponent'; please report this issue on https://yt-dl.org/bug . Make sure you are using the latest version; see  https://yt-dl.org/update  on how to update. Be sure to call youtube-dl with the --verbose flag and include its complete output.
 (caused by ExtractorError("Could not find JS function 'decodeURIComponent'; please report this issue on https://yt-dl.org/bug . Make sure you are using the latest version; see  https://yt-dl.org/update  on how to update. Be sure to call youtube-dl with the --verbose flag and include its complete output.")); please report this issue on https://yt-dl.org/bug . Make sure you are using the latest version; see  https://yt-dl.org/update  on how to update. Be sure to call youtube-dl with the --verbose flag and include its complete output.

The above exception was the direct cause of the following exception:

Traceback (most recent call last):
  File "C:\Users\ignac\Desktop\cosas PY\discord\botpy\Lib\site-packages\discord\ext\commands\bot.py", line 1350, in invoke
    await ctx.command.invoke(ctx)
  File "C:\Users\ignac\Desktop\cosas PY\discord\botpy\Lib\site-packages\discord\ext\commands\core.py", line 1029, in invoke
    await injected(*ctx.args, **ctx.kwargs)  # type: ignore
    ^^^^^^^^^^^^^^^^^^^^^^^^^^^^^^^^^^^^^^^
  File "C:\Users\ignac\Desktop\cosas PY\discord\botpy\Lib\site-packages\discord\ext\commands\core.py", line 244, in wrapped
    raise CommandInvokeError(exc) from exc
discord.ext.commands.errors.CommandInvokeError: Command raised an exception: DownloadError: ERROR: Signature extraction failed: Traceback (most recent call last):
  File "C:\Users\ignac\Desktop\cosas PY\discord\botpy\Lib\site-packages\youtube_dl\extractor\youtube.py", line 1360, in _decrypt_signature
    func = self._extract_signature_function(
           ^^^^^^^^^^^^^^^^^^^^^^^^^^^^^^^^^
  File "C:\Users\ignac\Desktop\cosas PY\discord\botpy\Lib\site-packages\youtube_dl\extractor\youtube.py", line 1274, in _extract_signature_function
    res = self._parse_sig_js(code)
          ^^^^^^^^^^^^^^^^^^^^^^^^
  File "C:\Users\ignac\Desktop\cosas PY\discord\botpy\Lib\site-packages\youtube_dl\extractor\youtube.py", line 1343, in _parse_sig_js
    initial_function = jsi.extract_function(funcname)
                       ^^^^^^^^^^^^^^^^^^^^^^^^^^^^^^
  File "C:\Users\ignac\Desktop\cosas PY\discord\botpy\Lib\site-packages\youtube_dl\jsinterp.py", line 245, in extract_function
    raise ExtractorError('Could not find JS function %r' % funcname)
youtube_dl.utils.ExtractorError: Could not find JS function 'decodeURIComponent'; please report this issue on https://yt-dl.org/bug . Make sure you are using the latest version; see  https://yt-dl.org/update  on how to update. Be sure to call youtube-dl with the --verbose flag and include its complete output.
 (caused by ExtractorError("Could not find JS function 'decodeURIComponent'; please report this issue on https://yt-dl.org/bug . Make sure you are using the latest version; see  https://yt-dl.org/update  on how to update. Be sure to call youtube-dl with the --verbose flag and include its complete output.")); please report this issue on https://yt-dl.org/bug . Make sure you are using the latest version; see  https://yt-dl.org/update  on how to update. Be sure to call youtube-dl with the --verbose flag and include its complete output.
2025-05-05 22:31:25,217 | ERROR | Ignoring exception in command play
Traceback (most recent call last):
  File "C:\Users\ignac\Desktop\cosas PY\discord\botpy\Lib\site-packages\discord\ext\commands\bot.py", line 1350, in invoke
    await ctx.command.invoke(ctx)
  File "C:\Users\ignac\Desktop\cosas PY\discord\botpy\Lib\site-packages\discord\ext\commands\core.py", line 1021, in invoke
    await self.prepare(ctx)
  File "C:\Users\ignac\Desktop\cosas PY\discord\botpy\Lib\site-packages\discord\ext\commands\core.py", line 938, in prepare
    await self._parse_arguments(ctx)
  File "C:\Users\ignac\Desktop\cosas PY\discord\botpy\Lib\site-packages\discord\ext\commands\core.py", line 853, in _parse_arguments
    kwargs[name] = await self.transform(ctx, param, attachments)
                   ^^^^^^^^^^^^^^^^^^^^^^^^^^^^^^^^^^^^^^^^^^^^^
  File "C:\Users\ignac\Desktop\cosas PY\discord\botpy\Lib\site-packages\discord\ext\commands\core.py", line 697, in transform
    raise MissingRequiredArgument(param)
discord.ext.commands.errors.MissingRequiredArgument: url is a required argument that is missing.
2025-05-05 22:31:32,077 | WARNING | Shard ID None has stopped responding to the gateway. Closing and restarting.
2025-05-05 22:31:57,370 | ERROR | Ignoring exception in command play
Traceback (most recent call last):
  File "C:\Users\ignac\Desktop\cosas PY\discord\botpy\Lib\site-packages\discord\ext\commands\bot.py", line 1350, in invoke
    await ctx.command.invoke(ctx)
  File "C:\Users\ignac\Desktop\cosas PY\discord\botpy\Lib\site-packages\discord\ext\commands\core.py", line 1021, in invoke
    await self.prepare(ctx)
  File "C:\Users\ignac\Desktop\cosas PY\discord\botpy\Lib\site-packages\discord\ext\commands\core.py", line 938, in prepare
    await self._parse_arguments(ctx)
  File "C:\Users\ignac\Desktop\cosas PY\discord\botpy\Lib\site-packages\discord\ext\commands\core.py", line 853, in _parse_arguments
    kwargs[name] = await self.transform(ctx, param, attachments)
                   ^^^^^^^^^^^^^^^^^^^^^^^^^^^^^^^^^^^^^^^^^^^^^
  File "C:\Users\ignac\Desktop\cosas PY\discord\botpy\Lib\site-packages\discord\ext\commands\core.py", line 697, in transform
    raise MissingRequiredArgument(param)
discord.ext.commands.errors.MissingRequiredArgument: url is a required argument that is missing.
2025-05-05 22:37:30,689 | INFO | The voice handshake is being terminated for Channel ID 805641564872376385 (Guild ID 805641564872376380)
2025-05-05 22:37:30,695 | ERROR | Ignoring exception in on_message
Traceback (most recent call last):
  File "C:\Program Files\Python311\Lib\asyncio\windows_events.py", line 471, in finish_recv
    return ov.getresult()
           ^^^^^^^^^^^^^^
OSError: [WinError 995] La operación de E/S se anuló por una salida de subproceso o por una solicitud de aplicación

During handling of the above exception, another exception occurred:

Traceback (most recent call last):
  File "C:\Users\ignac\Desktop\cosas PY\discord\botpy\Lib\site-packages\discord\ext\commands\core.py", line 235, in wrapped
    ret = await coro(*args, **kwargs)
          ^^^^^^^^^^^^^^^^^^^^^^^^^^^
  File "c:\Users\ignac\Desktop\cosas PY\discord\comandos\musica.py", line 103, in join
    await channel.connect()
  File "C:\Users\ignac\Desktop\cosas PY\discord\botpy\Lib\site-packages\discord\abc.py", line 1906, in connect
    await voice.connect(timeout=timeout, reconnect=reconnect, self_deaf=self_deaf, self_mute=self_mute)
  File "C:\Users\ignac\Desktop\cosas PY\discord\botpy\Lib\site-packages\discord\voice_client.py", line 395, in connect
    self.ws = await self.connect_websocket()
              ^^^^^^^^^^^^^^^^^^^^^^^^^^^^^^
  File "C:\Users\ignac\Desktop\cosas PY\discord\botpy\Lib\site-packages\discord\voice_client.py", line 366, in connect_websocket
    await ws.poll_event()
  File "C:\Users\ignac\Desktop\cosas PY\discord\botpy\Lib\site-packages\discord\gateway.py", line 1005, in poll_event
    await self.received_message(utils._from_json(msg.data))
  File "C:\Users\ignac\Desktop\cosas PY\discord\botpy\Lib\site-packages\discord\gateway.py", line 930, in received_message
    await self.initial_connection(data)
  File "C:\Users\ignac\Desktop\cosas PY\discord\botpy\Lib\site-packages\discord\gateway.py", line 957, in initial_connection
    recv = await self.loop.sock_recv(state.socket, 74)
           ^^^^^^^^^^^^^^^^^^^^^^^^^^^^^^^^^^^^^^^^^^^
  File "C:\Program Files\Python311\Lib\asyncio\proactor_events.py", line 705, in sock_recv
    return await self._proactor.recv(sock, n)
           ^^^^^^^^^^^^^^^^^^^^^^^^^^^^^^^^^^
  File "C:\Program Files\Python311\Lib\asyncio\windows_events.py", line 846, in _poll
    value = callback(transferred, key, ov)
            ^^^^^^^^^^^^^^^^^^^^^^^^^^^^^^
  File "C:\Program Files\Python311\Lib\asyncio\windows_events.py", line 475, in finish_recv
    raise ConnectionResetError(*exc.args)
ConnectionResetError: [WinError 995] La operación de E/S se anuló por una salida de subproceso o por una solicitud de aplicación

The above exception was the direct cause of the following exception:

Traceback (most recent call last):
  File "C:\Users\ignac\Desktop\cosas PY\discord\botpy\Lib\site-packages\discord\ext\commands\bot.py", line 1350, in invoke
    await ctx.command.invoke(ctx)
  File "C:\Users\ignac\Desktop\cosas PY\discord\botpy\Lib\site-packages\discord\ext\commands\core.py", line 1029, in invoke
    await injected(*ctx.args, **ctx.kwargs)  # type: ignore
    ^^^^^^^^^^^^^^^^^^^^^^^^^^^^^^^^^^^^^^^
  File "C:\Users\ignac\Desktop\cosas PY\discord\botpy\Lib\site-packages\discord\ext\commands\core.py", line 244, in wrapped
    raise CommandInvokeError(exc) from exc
discord.ext.commands.errors.CommandInvokeError: Command raised an exception: ConnectionResetError: [WinError 995] La operación de E/S se anuló por una salida de subproceso o por una solicitud de aplicación

During handling of the above exception, another exception occurred:

Traceback (most recent call last):
  File "C:\Users\ignac\Desktop\cosas PY\discord\botpy\Lib\site-packages\discord\client.py", line 441, in _run_event
    await coro(*args, **kwargs)
  File "C:\Users\ignac\Desktop\cosas PY\discord\botpy\Lib\site-packages\discord\ext\commands\bot.py", line 1395, in on_message
    await self.process_commands(message)
  File "C:\Users\ignac\Desktop\cosas PY\discord\botpy\Lib\site-packages\discord\ext\commands\bot.py", line 1392, in process_commands
    await self.invoke(ctx)  # type: ignore
    ^^^^^^^^^^^^^^^^^^^^^^
  File "C:\Users\ignac\Desktop\cosas PY\discord\botpy\Lib\site-packages\discord\ext\commands\bot.py", line 1354, in invoke
    await ctx.command.dispatch_error(ctx, exc)
  File "C:\Users\ignac\Desktop\cosas PY\discord\botpy\Lib\site-packages\discord\ext\commands\core.py", line 650, in dispatch_error
    ctx.bot.dispatch('command_error', ctx, error)
  File "C:\Users\ignac\Desktop\cosas PY\discord\botpy\Lib\site-packages\discord\ext\commands\bot.py", line 221, in dispatch
    super().dispatch(event_name, *args, **kwargs)  # type: ignore
    ^^^^^^^^^^^^^^^^^^^^^^^^^^^^^^^^^^^^^^^^^^^^^
  File "C:\Users\ignac\Desktop\cosas PY\discord\botpy\Lib\site-packages\discord\client.py", line 499, in dispatch
    self._schedule_event(coro, method, *args, **kwargs)
  File "C:\Users\ignac\Desktop\cosas PY\discord\botpy\Lib\site-packages\discord\client.py", line 459, in _schedule_event
    return self.loop.create_task(wrapped, name=f'discord.py: {event_name}')
           ^^^^^^^^^^^^^^^^^^^^^
AttributeError: '_MissingSentinel' object has no attribute 'create_task'
